<?xml version="1.0" ?>
<!-- =================================================================================== -->
<!-- |    This document was autogenerated by xacro from /home/match-mover/Documents/ros2_ws/install/pm_robot_description/share/pm_robot_description/urdf/pm_robot_main.xacro | -->
<!-- |    EDITING THIS FILE BY HAND IS NOT RECOMMENDED                                 | -->
<!-- =================================================================================== -->
<robot name="pm_robot">
  <material name="black">
    <color rgba="0.0 0.0 0.0 1.0"/>
  </material>
  <material name="blue">
    <color rgba="0.0 0.0 0.8 1.0"/>
  </material>
  <material name="green">
    <color rgba="0.0 0.8 0.0 1.0"/>
  </material>
  <material name="grey">
    <color rgba="0.2 0.2 0.2 1.0"/>
  </material>
  <material name="orange">
    <color rgba="1.0 0.4235294117647059 0.0392156862745098 1.0"/>
  </material>
  <material name="brown">
    <color rgba="0.8705882352941177 0.8117647058823529 0.7647058823529411 1.0"/>
  </material>
  <material name="red">
    <color rgba="0.8 0.0 0.0 1.0"/>
  </material>
  <material name="white">
    <color rgba="1.0 1.0 1.0 1.0"/>
  </material>
  <link name="world">
    </link>
  <joint name="world_joint" type="fixed">
    <parent link="world"/>
    <child link="base_link_empthy"/>
    <origin rpy="0 0 0" xyz="0 0 0"/>
  </joint>
  <!--%%%%%%%%%%%%% Base Link Definitions %%%%%%%%%%%%%-->
  <link name="base_link_empthy">
    </link>
  <!--%%%%%%%%%%%%% PM_Robot Base Link Definitions %%%%%%%%%%%%%-->
  <link name="pm_robot_base_link">
    <inertial>
      <origin rpy="0 0 0" xyz="0.600186355261373 0.60024822812755 -0.0500803495201262"/>
      <mass value="143.433412382625"/>
      <inertia ixx="17.331308476166" ixy="-0.000173857700061693" ixz="-0.00010330360577037" iyy="17.3263788236508" iyz="-0.00227792943650154" izz="34.4189883960519"/>
    </inertial>
    <visual>
      <origin rpy="0 0 0" xyz="0 0 0"/>
      <geometry>
        <mesh filename="package://meshes/pm_robot_base_link.STL"/>
      </geometry>
      <material name="">
        <color rgba="1 1 1 1"/>
      </material>
    </visual>
    <collision>
      <origin rpy="0 0 0" xyz="0 0 0"/>
      <geometry>
        <mesh filename="package://meshes/pm_robot_base_link.STL"/>
      </geometry>
    </collision>
  </link>
  <joint name="pm_robot_base_link_joint" type="fixed">
    <origin rpy="0 0 0" xyz="0 0 0.971"/>
    <parent link="base_link_empthy"/>
    <child link="pm_robot_base_link"/>
    <axis xyz="0 0 0"/>
  </joint>
  <!--%%%%%%%%%%%%% Axis-Base Definitions %%%%%%%%%%%%%-->
  <link name="axis_base">
    <inertial>
      <origin rpy="0 0 0" xyz="0.396220059353836 0.105196690337481 0.307909602405796"/>
      <mass value="43.6102590245999"/>
      <inertia ixx="0.364950648797973" ixy="-0.000379121082023338" ixz="0.00337088160159615" iyy="2.29090638523672" iyz="0.000705385684699142" izz="2.23411883185999"/>
    </inertial>
    <visual>
      <origin rpy="0 0 0" xyz="0 0 0"/>
      <geometry>
        <mesh filename="package://meshes/axis_base.STL"/>
      </geometry>
      <material name="">
        <color rgba="0.752941176470588 0.752941176470588 0.752941176470588 1"/>
      </material>
    </visual>
    <collision>
      <origin rpy="0 0 0" xyz="0 0 0"/>
      <geometry>
        <mesh filename="package://meshes/axis_base.STL"/>
      </geometry>
    </collision>
  </link>
  <joint name="axis_base_joint" type="fixed">
    <origin rpy="0 0 0" xyz="0.08001 0.632 1.000000000001E-05"/>
    <parent link="pm_robot_base_link"/>
    <child link="axis_base"/>
    <axis xyz="0 0 0"/>
  </joint>
  <!--%%%%%%%%%%%%% X Axis Definitions %%%%%%%%%%%%%-->
  <link name="X_Axis">
    <inertial>
      <origin rpy="0 0 0" xyz="0.13867117656886 0.0294673421865695 0.0322225410424505"/>
      <mass value="3.46651857022574"/>
      <inertia ixx="0.0263967056575219" ixy="-0.000746452162875097" ixz="-6.60103497268881E-06" iyy="0.0104790265642698" iyz="-0.000507544087069928" izz="0.0342327102580871"/>
    </inertial>
    <visual>
      <origin rpy="0 0 0" xyz="0 0 0"/>
      <geometry>
        <mesh filename="package://meshes/X_Axis.STL"/>
      </geometry>
      <material name="orange"/>
    </visual>
    <collision>
      <origin rpy="0 0 0" xyz="0 0 0"/>
      <geometry>
        <mesh filename="package://meshes/X_Axis.STL"/>
      </geometry>
    </collision>
  </link>
  <joint name="X_Axis_Joint" type="prismatic">
    <origin rpy="0 0 0" xyz="0.64699 0.11775 0.47499"/>
    <parent link="axis_base"/>
    <child link="X_Axis"/>
    <axis xyz="1 0 0"/>
    <limit effort="0.1" lower="-0.745" upper="0.055" velocity="35"/>
  </joint>
  <!--%%%%%%%%%%%%% Y Axis Definitions %%%%%%%%%%%%%-->
  <link name="Y_Axis">
    <inertial>
      <origin rpy="0 0 0" xyz="-0.00196813987548172 -0.3177998990051 0.113823941424653"/>
      <mass value="5.64847104935336"/>
      <inertia ixx="0.0734343917353869" ixy="-5.65230035141878E-06" ixz="-0.000161953758832679" iyy="0.0377139193260435" iyz="0.00720112978111611" izz="0.0598441739891415"/>
    </inertial>
    <visual>
      <origin rpy="0 0 0" xyz="0 0 0"/>
      <geometry>
        <mesh filename="package://meshes/Y_Axis.STL"/>
      </geometry>
      <material name="brown"/>
    </visual>
    <collision>
      <origin rpy="0 0 0" xyz="0 0 0"/>
      <geometry>
        <mesh filename="package://meshes/Y_Axis.STL"/>
      </geometry>
    </collision>
  </link>
  <joint name="Y_Axis_Joint" type="prismatic">
    <origin rpy="0 0 0" xyz="0.10865 0.25835 0.06525"/>
    <parent link="X_Axis"/>
    <child link="Y_Axis"/>
    <axis xyz="0 1 0"/>
    <limit effort="100" lower="-0.134000" upper="-0.019700" velocity="35"/>
  </joint>
  <!--%%%%%%%%%%%%% Z Axis Definitions %%%%%%%%%%%%%-->
  <link name="Z_Axis">
    <inertial>
      <origin rpy="0 0 0" xyz="0.000627664293855634 -0.00434675424374531 -0.2726241124114"/>
      <mass value="2.64388477073549"/>
      <inertia ixx="0.0168607348742555" ixy="-1.50786678765243E-05" ixz="-0.000199875277453675" iyy="0.0218740034837586" iyz="-8.24046242568125E-05" izz="0.00606496678568248"/>
    </inertial>
    <visual>
      <origin rpy="0 0 0" xyz="0 0 0"/>
      <geometry>
        <mesh filename="package://meshes/Z_Axis.STL"/>
      </geometry>
      <material name="blue"/>
    </visual>
    <collision>
      <origin rpy="0 0 0" xyz="0 0 0"/>
      <geometry>
        <mesh filename="package://meshes/Z_Axis.STL"/>
      </geometry>
    </collision>
  </link>
  <!---Gravity off-->
  <gazebo reference="Z_Axis">
    <turnGravityOff>true</turnGravityOff>
  </gazebo>
  <joint name="Z_Axis_Joint" type="prismatic">
    <origin rpy="0 0 0" xyz="-0.00365 -0.499 0.33875"/>
    <parent link="Y_Axis"/>
    <child link="Z_Axis"/>
    <axis xyz="0 0 -1"/>
    <limit effort="100" lower="-0.05262" upper="0.055" velocity="35"/>
  </joint>
  <!--%%%%%%%%%%%%% T Axis Definitions %%%%%%%%%%%%%-->
  <link name="Gripper_Rot_Plate">
    <inertial>
      <origin rpy="0 0 0" xyz="-1.74281094778017E-07 2.03483659588777E-07 0.00907792340584457"/>
      <mass value="0.110297257842221"/>
      <inertia ixx="8.79759467929701E-05" ixy="1.90651210379881E-10" ixz="1.25536613370482E-10" iyy="8.79764882626525E-05" iyz="-1.50065581017382E-10" izz="0.00016565987032676"/>
    </inertial>
    <visual>
      <origin rpy="0 0 0" xyz="0 0 0"/>
      <geometry>
        <mesh filename="package://meshes/Gripper_Rot_Plate.STL"/>
      </geometry>
      <material name="black"/>
    </visual>
    <collision>
      <origin rpy="0 0 0" xyz="0 0 0"/>
      <geometry>
        <mesh filename="package://meshes/Gripper_Rot_Plate.STL"/>
      </geometry>
    </collision>
  </link>
  <!---Gravity off-->
  <gazebo reference="Gripper_Rot_Plate">
    <turnGravityOff>true</turnGravityOff>
  </gazebo>
  <joint name="T_Axis_Joint" type="revolute">
    <origin rpy="0 0 0" xyz="0.0600000000000017 -0.0580000000000003 -0.427500000000004"/>
    <parent link="Z_Axis"/>
    <child link="Gripper_Rot_Plate"/>
    <axis xyz="0 0 1"/>
    <limit effort="100" lower="0" upper="12" velocity="5"/>
  </joint>
  <link name="t_axis_toolchanger">
    <inertial>
      <origin rpy="0 0 0" xyz="2.66657822625138E-05 -6.51697797860451E-05 -0.0173989628147272"/>
      <mass value="0.0770166396645032"/>
      <inertia ixx="1.38724675369177E-05" ixy="-2.81065278601148E-08" ixz="-4.32931581160332E-09" iyy="1.28173377099281E-05" iyz="-3.69738102041932E-10" izz="2.32495071670115E-05"/>
    </inertial>
    <visual>
      <origin rpy="0 0 0" xyz="0 0 0"/>
      <geometry>
        <mesh filename="package://meshes/t_axis_tool.STL"/>
      </geometry>
      <material name="">
        <color rgba="0.75294 0.75294 0.75294 1"/>
      </material>
    </visual>
    <collision>
      <origin rpy="0 0 0" xyz="0 0 0"/>
      <geometry>
        <mesh filename="package://meshes/t_axis_tool.STL"/>
      </geometry>
    </collision>
  </link>
  <!---Gravity off-->
  <gazebo reference="t_axis_toolchanger">
    <turnGravityOff>true</turnGravityOff>
  </gazebo>
  <joint name="t_axis_toolchanger_joint" type="fixed">
    <origin rpy="0 0 0" xyz="0 0 0"/>
    <parent link="Gripper_Rot_Plate"/>
    <child link="t_axis_toolchanger"/>
    <axis xyz="0 0 0"/>
  </joint>
  <link name="PM_Robot_Tool_TCP">
    </link>
  <joint name="PM_Robot_Tool_TCP_Joint" type="fixed">
    <!--Hier spaeter Variable-->
    <origin rpy="         0.0          0.0          0.0" xyz="         0.0          0.0          -0.08142"/>
    <parent link="Gripper_Rot_Plate"/>
    <child link="PM_Robot_Tool_TCP"/>
    <axis xyz="0 0 0"/>
  </joint>
  <!--%%%%%%%%%%%%% 1K Dispenser Flap Definitions %%%%%%%%%%%%%-->
  <link name="1K_Dispenser_Flap">
    <inertial>
      <origin rpy="0 0 0" xyz="-0.0475534171935499 -0.0152444446246764 -0.0129366605877314"/>
      <mass value="0.0179075605864254"/>
      <inertia ixx="4.17413884237766E-06" ixy="1.29835566651944E-07" ixz="6.2953731666034E-08" iyy="5.03313568637311E-06" iyz="9.02306176060272E-09" izz="4.11882542880041E-06"/>
    </inertial>
    <visual>
      <origin rpy="0 0 0" xyz="0 0 0"/>
      <geometry>
        <mesh filename="package://meshes/Glue_Cartridge_Flap.STL"/>
      </geometry>
      <material name="white"/>
    </visual>
    <collision>
      <origin rpy="0 0 0" xyz="0 0 0"/>
      <geometry>
        <mesh filename="package://meshes/Glue_Cartridge_Flap.STL"/>
      </geometry>
    </collision>
  </link>
  <!---Gravity off-->
  <gazebo reference="1K_Dispenser_Flap">
    <turnGravityOff>true</turnGravityOff>
  </gazebo>
  <joint name="1K_Dispenser_Flap_Joint" type="prismatic">
    <origin rpy="0 0 0" xyz="-0.0315 -0.02479 -0.424"/>
    <parent link="Z_Axis"/>
    <child link="1K_Dispenser_Flap"/>
    <axis xyz="1 0 0"/>
    <limit effort="100" lower="0" upper="0.02" velocity="0.05"/>
  </joint>
  <!--%%%%%%%%%%%%% 1K Dispenser Definitions %%%%%%%%%%%%%-->
  <link name="1K_Dispenser">
    <inertial>
      <origin rpy="0 0 0" xyz="-0.00291125760198996 -0.0158910684396169 -0.0486744620635529"/>
      <mass value="0.0741292037954837"/>
      <inertia ixx="3.4337175367919E-05" ixy="-1.91908706800505E-07" ixz="-5.62664674872138E-08" iyy="3.41011193217523E-05" iyz="5.66364181173195E-07" izz="1.14904781429849E-05"/>
    </inertial>
    <visual>
      <origin rpy="0 0 0" xyz="0 0 0"/>
      <geometry>
        <mesh filename="package://meshes/1K_Dispenser.STL"/>
      </geometry>
      <material name="grey"/>
    </visual>
    <collision>
      <origin rpy="0 0 0" xyz="0 0 0"/>
      <geometry>
        <mesh filename="package://meshes/1K_Dispenser.STL"/>
      </geometry>
    </collision>
  </link>
  <!---Gravity off-->
  <gazebo reference="1K_Dispenser">
    <turnGravityOff>true</turnGravityOff>
  </gazebo>
  <joint name="1K_Dispenser_Joint" type="prismatic">
    <origin rpy="0 0 0" xyz="-0.104 -0.0262 -0.3545"/>
    <parent link="Z_Axis"/>
    <child link="1K_Dispenser"/>
    <axis xyz="0 0 -1"/>
    <limit effort="100" lower="0" upper="0.04" velocity="0.05"/>
  </joint>
  <link name="1K_Dispenser_TCP">
    </link>
  <joint name="1K_Dispenser_TCP_Joint" type="fixed">
    <origin rpy="         0.0          0.0          0.0" xyz="         -0.001          -0.0318          -0.1285"/>
    <parent link="1K_Dispenser"/>
    <child link="1K_Dispenser_TCP"/>
    <axis xyz="0 0 0"/>
  </joint>
  <!--%%%%%%%%%%%%% 2K Dispenser Definitions-->
  <link name="2K_Dispenser_Cartridge">
    <inertial>
      <origin rpy="0 0 0" xyz="0.000286904622212703 -0.0363382955214142 0.157114812049142"/>
      <mass value="0.410111177184055"/>
      <inertia ixx="0.00156205497813664" ixy="-4.41612447012715E-06" ixz="-9.93222982118684E-08" iyy="0.00154767600658026" iyz="-1.49654417442962E-06" izz="0.000122541965999881"/>
    </inertial>
    <visual>
      <origin rpy="0 0 0" xyz="0 0 0"/>
      <geometry>
        <mesh filename="package://meshes/2K_Glue_Cartridge.STL"/>
      </geometry>
      <material name="white"/>
    </visual>
    <collision>
      <origin rpy="0 0 0" xyz="0 0 0"/>
      <geometry>
        <mesh filename="package://meshes/2K_Glue_Cartridge.STL"/>
      </geometry>
    </collision>
  </link>
  <!---Gravity off-->
  <gazebo reference="2K_Dispenser_Cartridge">
    <turnGravityOff>true</turnGravityOff>
  </gazebo>
  <joint name="2K_Dispenser_Joint" type="prismatic">
    <origin rpy="0 0 0" xyz="-0.169 0.01176 -0.424"/>
    <parent link="Z_Axis"/>
    <child link="2K_Dispenser_Cartridge"/>
    <axis xyz="0 0 -1"/>
    <limit effort="100" lower="0" upper="0.02" velocity="0.05"/>
  </joint>
  <link name="2K_Dispenser_TCP">
    </link>
  <joint name="2K_Dispenser_TCP_Joint" type="fixed">
    <origin rpy="         0.0          0.0          0.0" xyz="         0.0          -0.045          -0.04614"/>
    <parent link="2K_Dispenser_Cartridge"/>
    <child link="2K_Dispenser_TCP"/>
    <axis xyz="0 0 0"/>
  </joint>
  <!--%%%%%%%%%%%%% Top Camera Definitions-->
  <link name="Cam1_Toolhead_TCP">
    <inertial>
      <origin rpy="0 0 0" xyz="0.00294756628931103 0.0112908552453015 0.186544370768599"/>
      <mass value="0.222202026755256"/>
      <inertia ixx="0.000198536268283264" ixy="-2.57443493637635E-07" ixz="-2.33028260890714E-06" iyy="0.00020443076967091" iyz="-8.54446341843522E-06" izz="4.76896342979841E-05"/>
    </inertial>
    <visual>
      <origin rpy="0 0 0" xyz="0 0 0"/>
      <geometry>
        <mesh filename="package://meshes/Cam1_Toolhead_TCP.STL"/>
      </geometry>
      <material name="">
        <color rgba="0.752941176470588 0.752941176470588 0.752941176470588 1"/>
      </material>
    </visual>
    <collision>
      <origin rpy="0 0 0" xyz="0 0 0"/>
      <geometry>
        <mesh filename="package://meshes/Cam1_Toolhead_TCP.STL"/>
      </geometry>
    </collision>
  </link>
  <!---Gravity off-->
  <gazebo reference="Cam1_Toolhead_TCP">
    <turnGravityOff>true</turnGravityOff>
  </gazebo>
  <joint name="Cam1_Toolhead_TCP_Joint" type="fixed">
    <origin rpy="         0.0          0.0          0.0" xyz="         -0.0320000000000003          -0.0579999999999998          -0.515338706"/>
    <parent link="Z_Axis"/>
    <child link="Cam1_Toolhead_TCP"/>
    <axis xyz="0 0 0"/>
  </joint>
  <!--%%%%%%%%%%%%% Laser Toolhead Definitions-->
  <link name="Laser_Toolhead_TCP">
    <inertial>
      <origin rpy="0 0 0" xyz="0.00141971945625508 0.0148011051892054 0.0588118094043311"/>
      <mass value="0.185632781644417"/>
      <inertia ixx="0.00018384097226268" ixy="5.39428478530615E-09" ixz="-6.26322611599089E-07" iyy="0.000136967759808617" iyz="6.13082513214026E-07" izz="7.65210217467237E-05"/>
    </inertial>
    <visual>
      <origin rpy="0 0 0" xyz="0 0 0"/>
      <geometry>
        <mesh filename="package://meshes/Laser_Kopf_TCP.STL"/>
      </geometry>
      <material name="">
        <color rgba="0.752941176470588 0.752941176470588 0.752941176470588 1"/>
      </material>
    </visual>
    <collision>
      <origin rpy="0 0 0" xyz="0 0 0"/>
      <geometry>
        <mesh filename="package://meshes/Laser_Kopf_TCP.STL"/>
      </geometry>
    </collision>
  </link>
  <!---Gravity off-->
  <gazebo reference="Laser_Toolhead_TCP">
    <turnGravityOff>true</turnGravityOff>
  </gazebo>
  <joint name="Laser_Toolhead_TCP_Joint" type="fixed">
    <origin rpy="           0.0            0.0            0.0" xyz="           0.147498952947696            -0.0899999732334101            -0.495500000000011"/>
    <parent link="Z_Axis"/>
    <child link="Laser_Toolhead_TCP"/>
    <axis xyz="0 0 0"/>
  </joint>
  <!--%%%%%%%%%%%%% Test Station Definitions-->
  <link name="Test_Station">
    <inertial>
      <origin rpy="0 0 0" xyz="0.0250000000000002 0.0791274046351475 -0.154851137332961"/>
      <mass value="1.39099524679326"/>
      <inertia ixx="0.00780193904512034" ixy="-2.61717009512019E-14" ixz="-4.79910370720457E-20" iyy="0.00547600691976027" iyz="9.87499782602546E-10" izz="0.00281708795214926"/>
    </inertial>
    <visual>
      <origin rpy="0 0 0" xyz="0 0 0"/>
      <geometry>
        <mesh filename="package://meshes/Test_Station.STL"/>
      </geometry>
      <material name="white"/>
    </visual>
    <collision>
      <origin rpy="0 0 0" xyz="0 0 0"/>
      <geometry>
        <mesh filename="package://meshes/Test_Station.STL"/>
      </geometry>
    </collision>
  </link>
  <joint name="Test_Station_Joint" type="fixed">
    <origin rpy="0 0 0" xyz="0.075 0.3265 0.298"/>
    <parent link="pm_robot_base_link"/>
    <child link="Test_Station"/>
    <axis xyz="0 0 0"/>
  </joint>
  <!--%%%%%%%%%%%%% Camera Station Definitions-->
  <link name="Camera_Station">
    <inertial>
      <origin rpy="0 0 0" xyz="0.0886413519365855 0.189925462464436 0.138483690350839"/>
      <mass value="2.70231148841738"/>
      <inertia ixx="0.0183035942970588" ixy="1.26351026901094E-05" ixz="-2.79575355635167E-06" iyy="0.00441812287973743" iyz="5.22848888698871E-05" izz="0.0193956330708548"/>
    </inertial>
    <visual>
      <origin rpy="0 0 0" xyz="0 0 0"/>
      <geometry>
        <mesh filename="package://meshes/Camera_Station.STL"/>
      </geometry>
      <material name="white"/>
    </visual>
    <collision>
      <origin rpy="0 0 0" xyz="0 0 0"/>
      <geometry>
        <mesh filename="package://meshes/Camera_Station.STL"/>
      </geometry>
    </collision>
  </link>
  <joint name="Camera_Station_Joint" type="fixed">
    <origin rpy="0 0 0" xyz="0.4525 0.3125 0"/>
    <parent link="pm_robot_base_link"/>
    <child link="Camera_Station"/>
    <axis xyz="0 0 0"/>
  </joint>
  <link name="Camera_Station_TCP">
    </link>
  <joint name="Camera_Station_TCP_Joint" type="fixed">
    <origin rpy="         0.0          0.0          0.0" xyz="         0.08          0.092783          0.3045"/>
    <parent link="Camera_Station"/>
    <child link="Camera_Station_TCP"/>
    <axis xyz="0 0 0"/>
  </joint>
  <link name="Station_Laser_Bottom_TCP">
    <inertial>
      <origin rpy="0 0 0" xyz="0.00141971945625008 -0.0148011051892056 -0.0588118094043316"/>
      <mass value="0.185632781644417"/>
      <inertia ixx="0.000183840972262678" ixy="-5.39428478522435E-09" ixz="6.26322611589981E-07" iyy="0.000136967759808615" iyz="6.13082513215402E-07" izz="7.65210217467232E-05"/>
    </inertial>
    <visual>
      <origin rpy="0 0 0" xyz="0 0 0"/>
      <geometry>
        <mesh filename="package://meshes/Station_Laser_Bottom_TCP.STL"/>
      </geometry>
      <material name="">
        <color rgba="0.752941176470588 0.752941176470588 0.752941176470588 1"/>
      </material>
    </visual>
    <collision>
      <origin rpy="0 0 0" xyz="0 0 0"/>
      <geometry>
        <mesh filename="package://meshes/Station_Laser_Bottom_TCP.STL"/>
      </geometry>
    </collision>
  </link>
  <joint name="Station_Laser_Bottom_TCP_Joint" type="fixed">
    <origin rpy="           0.0            0.0            0.0" xyz="           0.1799989100971            0.0939999732334095            0.328499853483917"/>
    <parent link="Camera_Station"/>
    <child link="Station_Laser_Bottom_TCP"/>
    <axis xyz="0 0 0"/>
  </joint>
  <!--%%%%%%%%%%%%% Camera Calibration Definitions-->
  <link name="Camera_Calibration_Platelet">
    <inertial>
      <origin rpy="0 0 0" xyz="-0.000344499007125409 0.0696122748122424 0.000295151280628292"/>
      <mass value="0.0334016358510876"/>
      <inertia ixx="2.05104945364406E-05" ixy="-1.61006130053269E-08" ixz="-7.42638002033627E-11" iyy="2.64967112268826E-06" iyz="4.64472618194223E-07" izz="2.23824646029018E-05"/>
    </inertial>
    <visual>
      <origin rpy="0 0 0" xyz="0 0 0"/>
      <geometry>
        <mesh filename="package://meshes/Camera_Calibration_Platelet.STL"/>
      </geometry>
      <material name="green"/>
    </visual>
    <collision>
      <origin rpy="0 0 0" xyz="0 0 0"/>
      <geometry>
        <mesh filename="package://meshes/Camera_Calibration_Platelet.STL"/>
      </geometry>
    </collision>
  </link>
  <joint name="Camera_Calibration_Platelet_Joint" type="prismatic">
    <origin rpy="0 0 0" xyz="0.08 -0.0805 0.293"/>
    <parent link="Camera_Station"/>
    <child link="Camera_Calibration_Platelet"/>
    <axis xyz="0 -1 0"/>
    <limit effort="100" lower="-0.04" upper="0.0" velocity="0.05"/>
  </joint>
  <!--%%%%%%%%%%%%% Calibration Qube Definitions-->
  <link name="Calibration_Qube">
    <inertial>
      <origin rpy="0 0 0" xyz="0 -5.55111512312578E-17 -0.007418215969486"/>
      <mass value="0.000608132735199849"/>
      <inertia ixx="3.05434929012605E-04" ixy="2.70098962651108E-25" ixz="-1.09265340380468E-24" iyy="3.05434929012605E-04" iyz="6.45610037231024E-25" izz="5.52989859299796E-04"/>
    </inertial>
    <visual>
      <origin rpy="0 0 0" xyz="0 0 0"/>
      <geometry>
        <mesh filename="package://meshes/Calibration_Qube.STL"/>
      </geometry>
      <material name="green"/>
    </visual>
    <collision>
      <origin rpy="0 0 0" xyz="0 0 0"/>
      <geometry>
        <mesh filename="package://meshes/Calibration_Qube.STL"/>
      </geometry>
    </collision>
  </link>
  <!---Gravity off-->
  <gazebo reference="Calibration_Qube">
    <turnGravityOff>true</turnGravityOff>
  </gazebo>
  <joint name="Calibration_Qube_Joint" type="prismatic">
    <origin rpy="           0.0            0.0            0.0" xyz="           0.152            0.108            0.326"/>
    <parent link="Camera_Station"/>
    <child link="Calibration_Qube"/>
    <axis xyz="0 0 1"/>
    <limit effort="0" lower="-0.008" upper="0" velocity="0.005"/>
  </joint>
  <!--%%%%%%%%%%%%% Housing Definitions %%%%%%%%%%%%%-->
  <link name="housing_vl">
    <inertial>
      <origin rpy="0 0 0" xyz="0.106855071606918 -0.0365763858981578 0.4055"/>
      <mass value="15.7556351853533"/>
      <inertia ixx="0.894316439132711" ixy="0.0157593692116881" ixz="2.27661474248145E-18" iyy="0.894316439132711" iyz="-6.86930254496152E-17" izz="0.0614975233077981"/>
    </inertial>
    <visual>
      <origin rpy="0 0 0" xyz="0 0 0"/>
      <geometry>
        <mesh filename="package://meshes/Housing/housing_vl.STL"/>
      </geometry>
      <material name="red"/>
    </visual>
    <collision>
      <origin rpy="0 0 0" xyz="0 0 0"/>
      <geometry>
        <mesh filename="package://meshes/Housing/housing_vl.STL"/>
      </geometry>
    </collision>
  </link>
  <joint name="housing_vl_joint" type="fixed">
    <origin rpy="0 0 0" xyz="-0.198284271247462 -0.0548528137423858 0.11"/>
    <parent link="base_link_empthy"/>
    <child link="housing_vl"/>
    <axis xyz="0 0 0"/>
  </joint>
  <link name="housing_vr">
    <inertial>
      <origin rpy="0 0 0" xyz="0.0365763858981576 0.106855071606918 0.4055"/>
      <mass value="15.7556351853533"/>
      <inertia ixx="0.894316439132712" ixy="-0.0157593692116881" ixz="-2.21308886639773E-18" iyy="0.894316439132712" iyz="-6.04673492304204E-17" izz="0.0614975233077981"/>
    </inertial>
    <visual>
      <origin rpy="0 0 0" xyz="0 0 0"/>
      <geometry>
        <mesh filename="package://meshes/Housing/housing_vr.STL"/>
      </geometry>
      <material name="red"/>
    </visual>
    <collision>
      <origin rpy="0 0 0" xyz="0 0 0"/>
      <geometry>
        <mesh filename="package://meshes/Housing/housing_vr.STL"/>
      </geometry>
    </collision>
  </link>
  <joint name="housing_vr_joint" type="fixed">
    <origin rpy="0 0 0" xyz="1.25485281374239 -0.198284271247462 0.11"/>
    <parent link="base_link_empthy"/>
    <child link="housing_vr"/>
    <axis xyz="0 0 0"/>
  </joint>
  <link name="housing_hr">
    <inertial>
      <origin rpy="0 0 0" xyz="0.106855071606919 0.0365763858981576 -0.4055"/>
      <mass value="15.7556351853533"/>
      <inertia ixx="0.894316439132712" ixy="-0.015759369211688" ixz="3.2198946826335E-17" iyy="0.894316439132712" iyz="-8.14379058383444E-17" izz="0.0614975233077981"/>
    </inertial>
    <visual>
      <origin rpy="0 0 0" xyz="0 0 0"/>
      <geometry>
        <mesh filename="package://meshes/Housing/housing_hr.STL"/>
      </geometry>
      <material name="red"/>
    </visual>
    <collision>
      <origin rpy="0 0 0" xyz="0 0 0"/>
      <geometry>
        <mesh filename="package://meshes/Housing/housing_hr.STL"/>
      </geometry>
    </collision>
  </link>
  <joint name="housing_hr_joint" type="fixed">
    <origin rpy="-3.14159265358979 0 3.14159265358979" xyz="1.39828427124746 1.25485281374239 0.11"/>
    <parent link="base_link_empthy"/>
    <child link="housing_hr"/>
    <axis xyz="0 0 0"/>
  </joint>
  <link name="housing_hl">
    <inertial>
      <origin rpy="0 0 0" xyz="-0.0365763858981578 -0.106855071606918 0.4055"/>
      <mass value="15.7556351853533"/>
      <inertia ixx="0.894316439132711" ixy="-0.0157593692116881" ixz="-5.63429353481997E-18" iyy="0.894316439132711" iyz="-1.83506172989189E-16" izz="0.0614975233077981"/>
    </inertial>
    <visual>
      <origin rpy="0 0 0" xyz="0 0 0"/>
      <geometry>
        <mesh filename="package://meshes/Housing/housing_hl.STL"/>
      </geometry>
      <material name="red"/>
    </visual>
    <collision>
      <origin rpy="0 0 0" xyz="0 0 0"/>
      <geometry>
        <mesh filename="package://meshes/Housing/housing_hl.STL"/>
      </geometry>
    </collision>
  </link>
  <joint name="housing_hl_joint" type="fixed">
    <origin rpy="0 0 0" xyz="-0.0548528137423857 1.39828427124746 0.11"/>
    <parent link="base_link_empthy"/>
    <child link="housing_hl"/>
    <axis xyz="0 0 0"/>
  </joint>
  <link name="housing">
    <inertial>
      <origin rpy="0 0 0" xyz="0 0 0"/>
      <mass value="0"/>
      <inertia ixx="0" ixy="0" ixz="0" iyy="0" iyz="0" izz="0"/>
    </inertial>
    <visual>
      <origin rpy="0 0 0" xyz="0 0 0"/>
      <geometry>
        <mesh filename="package://meshes/Housing/housing.STL"/>
      </geometry>
      <material name="grey"/>
    </visual>
    <collision>
      <origin rpy="0 0 0" xyz="0 0 0"/>
      <geometry>
        <mesh filename="package://meshes/Housing/housing.STL"/>
      </geometry>
    </collision>
  </link>
  <joint name="housing_joint" type="fixed">
    <origin rpy="0 0 0" xyz="0 0 0"/>
    <parent link="base_link_empthy"/>
    <child link="housing"/>
    <axis xyz="0 0 0"/>
  </joint>
  <!--%%%%%%%%%%%%% MPG 10-plus Base Parallel Gripper Definitions %%%%%%%%%%%%%-->
  <link name="Tool_Gripper_MPG_10_Body">
    <inertial>
      <origin rpy="0 0 0" xyz="-5.33378479914543E-05 4.89879018877605E-05 0.0298093199815774"/>
      <mass value="0.018064299267735"/>
      <inertia ixx="2.10522678277741E-06" ixy="2.48405263011294E-08" ixz="-1.67008448737427E-08" iyy="1.54869219778472E-06" iyz="-7.34159323200004E-09" izz="3.42066952879888E-06"/>
    </inertial>
    <visual>
      <origin rpy="0 0 0" xyz="0 0 0"/>
      <geometry>
        <mesh filename="package://meshes/Tools/MPG_10_plus/Tool_MPG_10_Base.STL"/>
      </geometry>
      <material name="">
        <color rgba="0.752941176470588 0.752941176470588 0.752941176470588 1"/>
      </material>
    </visual>
    <collision>
      <origin rpy="0 0 0" xyz="0 0 0"/>
      <geometry>
        <mesh filename="package://meshes/Tools/MPG_10_plus/Tool_MPG_10_Base.STL"/>
      </geometry>
    </collision>
  </link>
  <!---Gravity off-->
  <gazebo reference="Tool_Gripper_MPG_10_Body">
    <turnGravityOff>true</turnGravityOff>
    <color>1.0 0 0.5 1.0</color>
  </gazebo>
  <joint name="Tool_Gripper_MPG_10_Body_Joint" type="fixed">
    <origin rpy="0 0 0" xyz="0 0 0"/>
    <parent link="PM_Robot_Tool_TCP"/>
    <child link="Tool_Gripper_MPG_10_Body"/>
    <axis xyz="0 0 0"/>
  </joint>
  <!--%%%%%%%%%%%%% MPG 10-plus Jaw 1 Parallel Gripper Definitions %%%%%%%%%%%%%-->
  <link name="Tool_Gripper_MPG_10_Jaw_1">
    <inertial>
      <origin rpy="0 0 0" xyz="0.00342309885399157 0.000378376833032924 -0.00384521007824437"/>
      <mass value="0.000125699746806344"/>
      <inertia ixx="9.10321731673149E-10" ixy="1.08017429109396E-10" ixz="-3.94221523852005E-10" iyy="1.46877530343563E-09" iyz="1.55511351427264E-10" izz="8.29097865963565E-10"/>
    </inertial>
    <visual>
      <origin rpy="0 0 0" xyz="0 0 0"/>
      <geometry>
        <mesh filename="package://meshes/Tools/MPG_10_plus/MPG_10_Jaw_1.STL"/>
      </geometry>
      <material name="">
        <color rgba="0.752941176470588 0.752941176470588 0.752941176470588 1"/>
      </material>
    </visual>
    <collision>
      <origin rpy="0 0 0" xyz="0 0 0"/>
      <geometry>
        <mesh filename="package://meshes/Tools/MPG_10_plus/MPG_10_Jaw_1.STL"/>
      </geometry>
    </collision>
  </link>
  <!---Gravity off-->
  <gazebo reference="Tool_Gripper_MPG_10_Jaw_1">
    <turnGravityOff>true</turnGravityOff>
  </gazebo>
  <joint name="pm_robot_Tool_Parallel_Joint" type="prismatic">
    <origin rpy="0 0 1.5708" xyz="0.00135 -0.005 0.0125"/>
    <parent link="Tool_Gripper_MPG_10_Body"/>
    <child link="Tool_Gripper_MPG_10_Jaw_1"/>
    <axis xyz="1 0 0"/>
    <limit effort="20" lower="0" upper="0.001" velocity="0.05"/>
  </joint>
  <link name="Tool_Gripper_MPG_10_Jaw_1_Point">
  </link>
  <joint name="Tool_Gripper_MPG_10_Jaw_1_Point_Joint" type="fixed">
    <origin rpy="0 0 0" xyz="0 0.0014 -0.0075"/>
    <parent link="Tool_Gripper_MPG_10_Jaw_1"/>
    <child link="Tool_Gripper_MPG_10_Jaw_1_Point"/>
    <axis xyz="0 0 0"/>
  </joint>
  <!--%%%%%%%%%%%%% MPG 10-plus Jaw 2 Parallel Gripper Definitions %%%%%%%%%%%%%-->
  <link name="Tool_Gripper_MPG_10_Jaw_2">
    <inertial>
      <origin rpy="0 0 0" xyz="0.00363289819353893 0.000378376833032925 -0.00384521007176004"/>
      <mass value="0.000125699746806344"/>
      <inertia ixx="9.10321731673149E-10" ixy="1.0801742729746E-10" ixz="-3.94221523852005E-10" iyy="1.46877530343563E-09" iyz="1.55511351102191E-10" izz="8.29097865963571E-10"/>
    </inertial>
    <visual>
      <origin rpy="0 0 0" xyz="0 0 0"/>
      <geometry>
        <mesh filename="package://meshes/Tools/MPG_10_plus/MPG_10_Jaw_2.STL"/>
      </geometry>
      <material name="">
        <color rgba="0.752941176470588 0.752941176470588 0.752941176470588 1"/>
      </material>
    </visual>
    <collision>
      <origin rpy="0 0 0" xyz="0 0 0"/>
      <geometry>
        <mesh filename="package://meshes/Tools/MPG_10_plus/MPG_10_Jaw_2.STL"/>
      </geometry>
    </collision>
  </link>
  <gazebo reference="Tool_Gripper_MPG_10_Jaw_2">
    <turnGravityOff>true</turnGravityOff>
  </gazebo>
  <joint name="pm_robot_Tool_Parallel_Joint_2" type="prismatic">
    <origin rpy="0 0 -1.5708" xyz="-0.00135 0.005 0.0125"/>
    <parent link="Tool_Gripper_MPG_10_Body"/>
    <child link="Tool_Gripper_MPG_10_Jaw_2"/>
    <axis xyz="1 0 0"/>
    <limit effort="20" lower="0" upper="0.001" velocity="0.05"/>
    <mimic joint="pm_robot_Tool_Parallel_Joint"/>
  </joint>
  <link name="Tool_Gripper_MPG_10_Jaw_2_Point">
  </link>
  <joint name="Tool_Gripper_MPG_10_Jaw_2_Point_Joint" type="fixed">
    <origin rpy="0 0 0" xyz="0 0.0014 -0.0075"/>
    <parent link="Tool_Gripper_MPG_10_Jaw_2"/>
    <child link="Tool_Gripper_MPG_10_Jaw_2_Point"/>
    <axis xyz="0 0 0"/>
  </joint>
  <!--%%%%%%%%%%%%% The parameters here are interchangeable %%%%%%%%%%%%%-->
  <!--%%%%%%%%%%%%% Jaw 1 Definitions %%%%%%%%%%%%%-->
  <link name="Tool_Gripper_MPG_10_Jaw_1_changeable">
    <inertial>
      <origin rpy="0 0 0" xyz="-0.00222703440519818 -1.24600850470724E-13 -0.0015303266892263"/>
      <mass value="0.000118476289547731"/>
      <inertia ixx="5.50616566102928e-10" ixy="1.15823081964001e-21" ixz="1.51586534634799e-10" iyy="6.62228324828861e-10" iyz="2.68654227697881e-20" izz="4.05699592387869e-10"/>
    </inertial>
    <visual>
      <origin rpy="0 0 0" xyz="0 0 0"/>
      <geometry>
        <mesh filename="package://meshes/Tools/MPG_10_plus/Jaws/Gripper_Jaw_1_3MM_Lens_for_MPG_10.STL"/>
      </geometry>
      <material name="">
        <color rgba="0.780392156862745 0.76078431372549 0.741176470588235 1"/>
      </material>
    </visual>
    <collision>
      <origin rpy="0 0 0" xyz="0 0 0"/>
      <geometry>
        <mesh filename="package://meshes/Tools/MPG_10_plus/Jaws/Gripper_Jaw_1_3MM_Lens_for_MPG_10.STL"/>
      </geometry>
    </collision>
  </link>
  <gazebo reference="Tool_Gripper_Jaw_1">
    <turnGravityOff>true</turnGravityOff>
  </gazebo>
  <joint name="Tool_Gripper_MPG_10_Jaw_1_changeable_Joint" type="fixed">
    <!-- This needs to be corrected in Solidworks -->
    <origin rpy="0 0 0" xyz="0.002 0 0 "/>
    <parent link="Tool_Gripper_MPG_10_Jaw_1_Point"/>
    <child link="Tool_Gripper_MPG_10_Jaw_1_changeable"/>
  </joint>
  <!--%%%%%%%%%%%%% Jaw 2 Definitions %%%%%%%%%%%%%-->
  <link name="Tool_Gripper_MPG_10_Jaw_2_changeable">
    <inertial>
      <origin rpy="0 0 0" xyz="-0.00224080580616211 -0.00152543365786503 1.2528765306995E-13"/>
      <mass value="0.000117826998616915"/>
      <inertia ixx="5.504084274466e-10" ixy="1.50894936754082e-10" ixz="-1.43349001887448e-21" iyy="4.00144751949544e-10" iyz="-2.68169098626193e-20" izz="6.58370363267184e-10"/>
    </inertial>
    <visual>
      <origin rpy="0 0 0" xyz="0 0 0"/>
      <geometry>
        <mesh filename="package://meshes/Tools/MPG_10_plus/Jaws/Gripper_Jaw_2_3MM_Lens_for_MPG_10.STL"/>
      </geometry>
      <material name="">
        <color rgba="0.780392156862745 0.76078431372549 0.741176470588235 1"/>
      </material>
    </visual>
    <collision>
      <origin rpy="0 0 0" xyz="0 0 0"/>
      <geometry>
        <mesh filename="package://meshes/Tools/MPG_10_plus/Jaws/Gripper_Jaw_2_3MM_Lens_for_MPG_10.STL"/>
      </geometry>
    </collision>
  </link>
  <gazebo reference="Tool_Gripper_MPG_10_Jaw_2_changeable">
    <turnGravityOff>true</turnGravityOff>
  </gazebo>
  <joint name="Tool_Gripper_MPG_10_Jaw_2_changeable_Joint" type="fixed">
    <!-- This needs to be corrected in Solidworks -->
    <origin rpy="1.5708 0 0" xyz="0.002 0  0 "/>
    <parent link="Tool_Gripper_MPG_10_Jaw_2_Point"/>
    <child link="Tool_Gripper_MPG_10_Jaw_2_changeable"/>
  </joint>
  <!--%%%%%%%%%%%%% SPT-Vacuumgripper Definitions %%%%%%%%%%%%%-->
  <link name="Tool_Schunk_SPT_Toolholder">
    <inertial>
      <origin rpy="0 0 0" xyz="-1.29186788957441E-21 7.60244056032738E-20 0.00881061215391388"/>
      <mass value="0.000106303297474693"/>
      <inertia ixx="2.11600644479187E-09" ixy="8.13665451291654E-43" ixz="6.03059354626119E-28" iyy="2.11600644479187E-09" iyz="1.8508053225459E-26" izz="1.3734100235101E-10"/>
    </inertial>
    <visual>
      <origin rpy="0 0 0" xyz="0 0 0"/>
      <geometry>
        <mesh filename="package://meshes/Tools/SPT_Vacuumtools/Tool_Schunk_Holder_SPT.STL"/>
      </geometry>
      <material name="orange"/>
    </visual>
    <collision>
      <origin rpy="0 0 0" xyz="0 0 0"/>
      <geometry>
        <mesh filename="package://meshes/Tools/SPT_Vacuumtools/Tool_Schunk_Holder_SPT.STL"/>
      </geometry>
    </collision>
  </link>
  <!---Gravity off-->
  <gazebo reference="Tool_Schunk_SPT_Toolholder">
    <turnGravityOff>true</turnGravityOff>
    <color>1.0 0 0.5 1.0</color>
  </gazebo>
  <joint name="Tool_Schunk_SPT_Toolholder_Joint" type="fixed">
    <!-- <origin xyz="0 0 -0.06" rpy="0 0 0" /> -->
    <origin rpy="0 0 0" xyz="0 0 0"/>
    <parent link="PM_Robot_Tool_TCP"/>
    <child link="Tool_Schunk_SPT_Toolholder"/>
    <axis xyz="0 0 0"/>
  </joint>
  <!--
        %%%%%%%%%%%%% SPT-Vacuumgripper Tool Link Definitions %%%%%%%%%%%%%
        <link name="Tool_SPT_base_link">
        </link>

        <joint name="Tool_SPT_base_link_joint" type="fixed">
            <origin xyz="0 0 -0.012" rpy="0 0 0" />

            <parent link="Tool_Schunk_SPT_Toolholder" />
            <child link="Tool_SPT_base_link" />
            <axis xyz="0 0 0" />
        </joint
        -->
  <!--%%%%%%%%%%%% Tool_TCP_SPT_R_A1000_I500 %%%%%%%%%%%%%-->
  <link name="Tool_SPT_changeable">
    <inertial>
      <origin rpy="0 0 0" xyz="-1.29186788957441E-21 7.60244056032738E-20 0.00881061215391388"/>
      <mass value="0.000106303297474693"/>
      <inertia ixx="2.11600644479187E-09" ixy="8.13665451291654E-43" ixz="6.0305935462612E-28" iyy="2.11600644479187E-09" iyz="1.8508053225459E-26" izz="1.3734100235101E-10"/>
    </inertial>
    <visual>
      <origin rpy="0 0 0" xyz="0 0 0"/>
      <geometry>
        <mesh filename="package://meshes/Tools/SPT_Vacuumtools/Tools/Tool_TCP_SPT_R_A1000_I500.STL"/>
      </geometry>
      <material name="grey"/>
    </visual>
    <collision>
      <origin rpy="0 0 0" xyz="0 0 0"/>
      <geometry>
        <mesh filename="package://meshes/Tools/SPT_Vacuumtools/Tools/Tool_TCP_SPT_R_A1000_I500.STL"/>
      </geometry>
    </collision>
  </link>
  <!--Gravity off-->
  <gazebo reference="Tool_SPT_changeable">
    <turnGravityOff>true</turnGravityOff>
    <color>1.0 0 0.5 1.0</color>
  </gazebo>
  <joint name="Tool_SPT_changeable_joint" type="fixed">
    <origin rpy="0 0 0" xyz="0 0 0"/>
    <parent link="PM_Robot_Tool_TCP"/>
    <child link="Tool_SPT_changeable"/>
    <axis xyz="0 0 0"/>
  </joint>
  <!--%%%%%%%%%%%%% Gonio_Right Definitions %%%%%%%%-->
  <link name="Gonio_Base_Right">
    <inertial>
      <origin rpy="0 0 0" xyz="0.0750000000000001 0.0875 0.0967750321735945"/>
      <mass value="0.735149712395275"/>
      <inertia ixx="0.00216092025189497" ixy="-1.14771309991733E-20" ixz="-3.69522069861046E-19" iyy="0.00218184071743384" iyz="5.29016162077308E-20" izz="0.000537834506363752"/>
    </inertial>
    <visual>
      <origin rpy="0 0 0" xyz="0 0 0"/>
      <geometry>
        <mesh filename="package://meshes/Gonio_Right/Gonio_Base_Right.STL"/>
      </geometry>
      <material name="white"/>
    </visual>
    <collision>
      <origin rpy="0 0 0" xyz="0 0 0"/>
      <geometry>
        <mesh filename="package://meshes/Gonio_Right/Gonio_Base_Right.STL"/>
      </geometry>
    </collision>
  </link>
  <joint name="Gonio_Base_Right_Joint" type="fixed">
    <origin rpy="0 0 0" xyz="0.750000000000003 0.31 0"/>
    <parent link="pm_robot_base_link"/>
    <child link="Gonio_Base_Right"/>
    <axis xyz="0 0 0"/>
  </joint>
  <!--%%%%%%%%%%%%% Gonio_Right Stage Bottom Definitions-->
  <link name="Gonio_Right_Stage_1_Bottom">
    <inertial>
      <origin rpy="0 0 0" xyz="0.0473956245440273 0.0326775285629692 0.00802879322662528"/>
      <mass value="0.0706349432835732"/>
      <inertia ixx="1.8004068123271E-05" ixy="7.72258833076008E-11" ixz="1.39266767162876E-07" iyy="3.36962706733938E-05" iyz="-1.91981813996212E-11" izz="4.86217530226206E-05"/>
    </inertial>
    <visual>
      <origin rpy="0 0 0" xyz="0 0 0"/>
      <geometry>
        <mesh filename="package://meshes/Gonio_Right/Gonio_Right_Stage_1.STL"/>
      </geometry>
      <material name="grey"/>
    </visual>
    <collision>
      <origin rpy="0 0 0" xyz="0 0 0"/>
      <geometry>
        <mesh filename="package://meshes/Gonio_Right/Gonio_Right_Stage_1.STL"/>
      </geometry>
    </collision>
  </link>
  <!---Gravity off-->
  <gazebo reference="Gonio_Right_Stage_1_Bottom">
    <turnGravityOff>true</turnGravityOff>
  </gazebo>
  <joint name="Gonio_Right_Stage_1_Bottom_Joint" type="fixed">
    <origin rpy="0 0 0" xyz="0.0425000000000001 0.055 0.1847"/>
    <parent link="Gonio_Base_Right"/>
    <child link="Gonio_Right_Stage_1_Bottom"/>
    <axis xyz="0 0 0"/>
  </joint>
  <!--%%%%%%%%%%%%% Gonio_Right Stage 1 Top Definitions-->
  <link name="Gonio_Right_Stage_1_Top">
    <inertial>
      <origin rpy="0 0 0" xyz="-1.23867349599571E-07 0.00776563461425855 -0.0788347959618214"/>
      <mass value="0.135485828183631"/>
      <inertia ixx="6.29207513367842E-05" ixy="-8.20165428667741E-11" ixz="3.32779841696372E-11" iyy="4.16210408086872E-05" iyz="1.10769519244758E-07" izz="9.7190851412307E-05"/>
    </inertial>
    <visual>
      <origin rpy="0 0 0" xyz="0 0 0"/>
      <geometry>
        <mesh filename="package://meshes/Gonio_Right/Gonio_Right_Stage_1_Upper.STL"/>
      </geometry>
      <material name="white"/>
    </visual>
    <collision>
      <origin rpy="0 0 0" xyz="0 0 0"/>
      <geometry>
        <mesh filename="package://meshes/Gonio_Right/Gonio_Right_Stage_1_Upper.STL"/>
      </geometry>
    </collision>
  </link>
  <!---Gravity off-->
  <gazebo reference="Gonio_Right_Stage_1_Top">
    <turnGravityOff>true</turnGravityOff>
  </gazebo>
  <joint name="Gonio_Right_Stage_1_Joint" type="revolute">
    <origin rpy="0 0 0" xyz="0.0324999999999993 0.0326774999999999 0.11"/>
    <parent link="Gonio_Right_Stage_1_Bottom"/>
    <child link="Gonio_Right_Stage_1_Top"/>
    <axis xyz="0 -1 0"/>
    <limit effort="100" lower="-0.087266" upper="0.087266" velocity="0.1"/>
  </joint>
  <!--%%%%%%%%%%%%% Gonio_Right Stage 2 Bottom Definitions-->
  <link name="Gonio_Right_Stage_2_Bottom">
    <inertial>
      <origin rpy="0 0 0" xyz="8.11599898398185E-10 -7.70700947505532E-10 -0.0578599597513433"/>
      <mass value="0.0546397543064688"/>
      <inertia ixx="1.83573872586574E-05" ixy="1.02198811435971E-11" ixz="3.03498623147601E-13" iyy="2.38958828661973E-05" iyz="8.61195754462734E-13" izz="3.93608749922961E-05"/>
    </inertial>
    <visual>
      <origin rpy="0 0 0" xyz="0 0 0"/>
      <geometry>
        <mesh filename="package://meshes/Gonio_Right/Gonio_Right_Stage_2_Upper.STL"/>
      </geometry>
      <material name="grey"/>
    </visual>
    <collision>
      <origin rpy="0 0 0" xyz="0 0 0"/>
      <geometry>
        <mesh filename="package://meshes/Gonio_Right/Gonio_Right_Stage_2_Upper.STL"/>
      </geometry>
    </collision>
  </link>
  <!---Gravity off-->
  <gazebo reference="Gonio_Right_Stage_2_Bottom">
    <turnGravityOff>true</turnGravityOff>
  </gazebo>
  <joint name="Gonio_Right_Stage_2_Joint" type="revolute">
    <origin rpy="0 0 0" xyz="0 0 0"/>
    <parent link="Gonio_Right_Stage_1_Top"/>
    <child link="Gonio_Right_Stage_2_Bottom"/>
    <axis xyz="-1 0 0"/>
    <limit effort="100" lower="-0.17453" upper="0.17453" velocity="0.1"/>
  </joint>
  <!--%%%%%%%%%%%%% Gonio Right Chuck Definitions-->
  <link name="Gonio_Right_Chuck">
  </link>
  <joint name="Gonio_Right_Chuck_Joint" type="fixed">
    <origin rpy="0 0 0" xyz="0 0 -0.0499999999999999"/>
    <parent link="Gonio_Right_Stage_2_Bottom"/>
    <child link="Gonio_Right_Chuck"/>
    <axis xyz="0 0 0"/>
  </joint>
  <!--%%%%%%%%%%%%% Gonio Right Part Origin -->
  <link name="Gonio_Right_Part_Origin">
  </link>
  <joint name="Gonio_Right_Part_Origin_Joint" type="fixed">
    <origin rpy="0 0 0" xyz="0 0 0"/>
    <parent link="Gonio_Right_Chuck"/>
    <child link="Gonio_Right_Part_Origin"/>
    <axis xyz="0 0 0"/>
  </joint>
  <!--%%%%%%%%%%%%% This is a Chuck Example -->
  <link name="Gonio_Right_Example_Chuck">
    <inertial>
      <origin rpy="0 0 0" xyz="-4.91275391850676E-05 -7.08920350384057E-06 0.0216564841336891"/>
      <mass value="0.133934804202608"/>
      <inertia ixx="3.05433990945277E-05" ixy="-2.55507616624267E-10" ixz="-1.7486699307754E-08" iyy="4.80787890381723E-05" iyz="2.24246430305895E-09" izz="7.18729232269431E-05"/>
    </inertial>
    <visual>
      <origin rpy="0 0 0" xyz="0 0 0"/>
      <geometry>
        <mesh filename="package://meshes/Gonio_Right/Gonio_Right_Chuck.STL"/>
      </geometry>
      <material name="">
        <color rgba="0.752941176470588 0.752941176470588 0.752941176470588 1"/>
      </material>
    </visual>
    <collision>
      <origin rpy="0 0 0" xyz="0 0 0"/>
      <geometry>
        <mesh filename="package://meshes/Gonio_Right/Gonio_Right_Chuck.STL"/>
      </geometry>
    </collision>
  </link>
  <joint name="Gonio_Right_Example_Chuck_Joint" type="fixed">
    <origin rpy="0 0 0" xyz="0 0 0"/>
    <parent link="Gonio_Right_Chuck"/>
    <child link="Gonio_Right_Example_Chuck"/>
    <axis xyz="0 0 0"/>
  </joint>
  <!--%%%%%%%%%%%%% Gonio Station Left Definitions-->
  <link name="Gonio_Left_Base">
    <inertial>
      <origin rpy="0 0 0" xyz="0.178376501584756 0.0965486243516244 0.101012071321914"/>
      <mass value="4.83318673735945"/>
      <inertia ixx="0.0115124478906001" ixy="4.00480442649554E-05" ixz="-5.80448319957772E-07" iyy="0.0188689063295654" iyz="-2.7716346407679E-05" izz="0.0269850736598033"/>
    </inertial>
    <visual>
      <origin rpy="0 0 0" xyz="0 0 0"/>
      <geometry>
        <mesh filename="package://meshes/Gonio_Left/Gonio_Left_Base.STL"/>
      </geometry>
      <material name="white"/>
    </visual>
    <collision>
      <origin rpy="0 0 0" xyz="0 0 0"/>
      <geometry>
        <mesh filename="package://meshes/Gonio_Left/Gonio_Left_Base.STL"/>
      </geometry>
    </collision>
  </link>
  <joint name="Gonio_Left_Base_Joint" type="fixed">
    <origin rpy="0 0 0" xyz="0.14249999999998 0.295499999999939 0"/>
    <parent link="pm_robot_base_link"/>
    <child link="Gonio_Left_Base"/>
    รถ
    
    <axis xyz="0 0 0"/>
  </joint>
  <!--%%%%%%%%%%%%% Gonio Left Stage 1 Top Definitions-->
  <link name="Gonio_Left_Stage_1_Top">
    <inertial>
      <origin rpy="0 0 0" xyz="0.059454973286124 0.0107762403389283 -0.0446785627316242"/>
      <mass value="0.578798857286943"/>
      <inertia ixx="0.000410450617020548" ixy="-0.000168393668986117" ixz="9.5803621154249E-07" iyy="0.00156907354726657" iyz="-5.23053452301373E-06" izz="0.00188005175520343"/>
    </inertial>
    <visual>
      <origin rpy="0 0 0" xyz="0 0 0"/>
      <geometry>
        <mesh filename="package://meshes/Gonio_Left/Gonio_Left_Stage_1.STL"/>
      </geometry>
      <material name="grey"/>
    </visual>
    <collision>
      <origin rpy="0 0 0" xyz="0 0 0"/>
      <geometry>
        <mesh filename="package://meshes/Gonio_Left/Gonio_Left_Stage_1.STL"/>
      </geometry>
    </collision>
  </link>
  <!---Gravity off-->
  <gazebo reference="Gonio_Left_Stage_1_Top">
    <turnGravityOff>true</turnGravityOff>
  </gazebo>
  <joint name="Gonio_Left_Stage_1_Joint" type="revolute">
    <origin rpy="0 0 0" xyz="0.188500000000042 0.110000000000054 0.212499999999997"/>
    <parent link="Gonio_Left_Base"/>
    <child link="Gonio_Left_Stage_1_Top"/>
    <axis xyz="1 0 0"/>
    <limit effort="100" lower="-0.17453" upper="0.17453" velocity="0.1"/>
  </joint>
  <!--%%%%%%%%%%%%% Gonio Left Stage 2 Bottom Definitions-->
  <link name="Gonio_Left_Stage_2_Bottom">
    <inertial>
      <origin rpy="0 0 0" xyz="4.69384364709668E-10 1.57268642553277E-11 -0.00620045721380197"/>
      <mass value="0.0270626701992899"/>
      <inertia ixx="6.08566105952436E-06" ixy="5.75557428925166E-08" ixz="-8.6517331846629E-13" iyy="4.36978117330268E-06" iyz="-2.89879120608969E-14" izz="9.60640029376035E-06"/>
    </inertial>
    <visual>
      <origin rpy="0 0 0" xyz="0 0 0"/>
      <geometry>
        <mesh filename="package://meshes/Gonio_Left/Gonio_Left_Stage_2.STL"/>
      </geometry>
      <material name="white"/>
    </visual>
    <collision>
      <origin rpy="0 0 0" xyz="0 0 0"/>
      <geometry>
        <mesh filename="package://meshes/Gonio_Left/Gonio_Left_Stage_2.STL"/>
      </geometry>
    </collision>
  </link>
  <!---Gravity off-->
  <gazebo reference="Gonio_Left_Stage_2_Joint">
    <turnGravityOff>true</turnGravityOff>
  </gazebo>
  <joint name="Gonio_Left_Stage_2_Joint" type="revolute">
    <origin rpy="0 0 0" xyz="0 0 0"/>
    <parent link="Gonio_Left_Stage_1_Top"/>
    <child link="Gonio_Left_Stage_2_Bottom"/>
    <axis xyz="0.0334865202089474 -0.999439169216564 0"/>
    <limit effort="100" lower="-0.17453" upper="0.17453" velocity="0.1"/>
  </joint>
  <!--%%%%%%%%%%%%% Gonio Left Chuck Definitions-->
  <link name="Gonio_Left_Chuck">
  </link>
  <joint name="Gonio_Left_Chuck_Joint" type="fixed">
    <origin rpy="0 0 0" xyz="0 0 -0.015"/>
    <parent link="Gonio_Left_Stage_2_Bottom"/>
    <child link="Gonio_Left_Chuck"/>
    <axis xyz="0 0 0"/>
  </joint>
  <link name="Gonio_Left_Part_Origin">
  </link>
  <joint name="Gonio_Left_Part_Origin_Joint" type="fixed">
    <origin rpy="0 0 0" xyz="0 0 0"/>
    <parent link="Gonio_Left_Chuck"/>
    <child link="Gonio_Left_Part_Origin"/>
    <axis xyz="0 0 0"/>
  </joint>
  <!--%%%%%%%%%%%%% Gonio Left Example Chuck Definitions-->
  <link name="Gonio_Left_Example_Chuck">
    <inertial>
      <origin rpy="0 0 0" xyz="0.00851660407252697 0.00736263697453748 0.0446054201819609"/>
      <mass value="0.193859196068301"/>
      <inertia ixx="6.74557361964199E-05" ixy="-1.48218596250914E-05" ixz="-9.56044333605206E-07" iyy="0.000514689088229689" iyz="-1.14966587929801E-06" izz="0.00047114586366426"/>
    </inertial>
    <visual>
      <origin rpy="0 0 0" xyz="0 0 0"/>
      <geometry>
        <mesh filename="package://meshes/Gonio_Left/Gonio_Left_Chuck.STL"/>
      </geometry>
      <material name="">
        <color rgba="0.752941176470588 0.752941176470588 0.752941176470588 1"/>
      </material>
    </visual>
    <collision>
      <origin rpy="0 0 0" xyz="0 0 0"/>
      <geometry>
        <mesh filename="package://meshes/Gonio_Left/Gonio_Left_Chuck.STL"/>
      </geometry>
    </collision>
  </link>
  <!---Gravity off-->
  <gazebo reference="Gonio_Left_Example_Chuck">
    <turnGravityOff>true</turnGravityOff>
  </gazebo>
  <joint name="Gonio_Left_Example_Chuck_Joint" type="fixed">
    <origin rpy="0 0 0" xyz="0 0 0"/>
    <parent link="Gonio_Left_Chuck"/>
    <child link="Gonio_Left_Example_Chuck"/>
    <axis xyz="0 0 0"/>
  </joint>
  <!--%%%%%%%%%%%%% UV Slider X Front Definitions-->
  <link name="UV_Slider_X_Front">
    <inertial>
      <origin rpy="0 0 0" xyz="0.0678075668801579 -0.00614110312679139 0.0281452705871906"/>
      <mass value="0.123081615016624"/>
      <inertia ixx="5.17246869963476E-05" ixy="5.73233720860217E-08" ixz="1.10286553709345E-07" iyy="6.01963900555089E-05" iyz="-1.95135766107832E-09" izz="0.0001085863059652"/>
    </inertial>
    <visual>
      <origin rpy="0 0 0" xyz="0 0 0"/>
      <geometry>
        <mesh filename="package://meshes/Gonio_Left/UV_Cart_X_Front.STL"/>
      </geometry>
      <material name="white"/>
    </visual>
    <collision>
      <origin rpy="0 0 0" xyz="0 0 0"/>
      <geometry>
        <mesh filename="package://meshes/Gonio_Left/UV_Cart_X_Front.STL"/>
      </geometry>
    </collision>
  </link>
  <joint name="UV_Slider_X_Front_Joint" type="prismatic">
    <origin rpy="0 0 0" xyz="0.0785000000000391 0.0200000000000492 0.234999999999997"/>
    <parent link="Gonio_Left_Base"/>
    <child link="UV_Slider_X_Front"/>
    <axis xyz="1 0 0"/>
    <limit effort="100" lower="0" upper="0.095" velocity="0.05"/>
  </joint>
  <!--%%%%%%%%%%%%% UV LED Front Definitions-->
  <link name="UV_LED_Front">
    <inertial>
      <origin rpy="0 0 0" xyz="0.00149625706477036 0.00485466541438256 0.010590788590885"/>
      <mass value="0.119915229322348"/>
      <inertia ixx="8.58688559917156E-05" ixy="-9.33412701053303E-06" ixz="2.12947225159946E-07" iyy="1.98652848189388E-05" iyz="9.66953808700587E-07" izz="0.00010123498655613"/>
    </inertial>
    <visual>
      <origin rpy="0 0 0" xyz="0 0 0"/>
      <geometry>
        <mesh filename="package://meshes/Gonio_Left/UV_Cart_Front.STL"/>
      </geometry>
      <material name="grey"/>
    </visual>
    <collision>
      <origin rpy="0 0 0" xyz="0 0 0"/>
      <geometry>
        <mesh filename="package://meshes/Gonio_Left/UV_Cart_Front.STL"/>
      </geometry>
    </collision>
  </link>
  <joint name="UV_LED_Front_Joint" type="prismatic">
    <origin rpy="0 0 0" xyz="0.0649999999999999 -0.0540000000000002 0.0496999999988213"/>
    <parent link="UV_Slider_X_Front"/>
    <child link="UV_LED_Front"/>
    <axis xyz="0 1 0"/>
    <limit effort="100" lower="0" upper="0.01" velocity="0.05"/>
  </joint>
  <!--%%%%%%%%%%%%% UV Slider X Back Definitions-->
  <link name="UV_Slider_X_Back">
    <inertial>
      <origin rpy="0 0 0" xyz="0.0621924331202753 0.00614110312652594 0.0281452705830895"/>
      <mass value="0.123081615017413"/>
      <inertia ixx="5.17246869964295E-05" ixy="5.73233722279355E-08" ixz="-1.10286553628501E-07" iyy="6.01963900556179E-05" iyz="1.95135762598339E-09" izz="0.000108586305965351"/>
    </inertial>
    <visual>
      <origin rpy="0 0 0" xyz="0 0 0"/>
      <geometry>
        <mesh filename="package://meshes/Gonio_Left/UV_Cart_X_Back.STL"/>
      </geometry>
      <material name="white"/>
    </visual>
    <collision>
      <origin rpy="0 0 0" xyz="0 0 0"/>
      <geometry>
        <mesh filename="package://meshes/Gonio_Left/UV_Cart_X_Back.STL"/>
      </geometry>
    </collision>
  </link>
  <joint name="UV_Slider_X_Back_Joint" type="prismatic">
    <origin rpy="0 0 0" xyz="0.0785000000000389 0.200000000000049 0.234999999999998"/>
    <parent link="Gonio_Left_Base"/>
    <child link="UV_Slider_X_Back"/>
    <axis xyz="1 0 0"/>
    <limit effort="0.05" lower="0" upper="0.045" velocity="100"/>
  </joint>
  <!--%%%%%%%%%%%%% UV LED Back Definitions-->
  <link name="UV_LED_Back">
    <inertial>
      <origin rpy="0 0 0" xyz="-0.00149625706477086 -0.00485466541438306 0.0105907885908847"/>
      <mass value="0.119915229322348"/>
      <inertia ixx="8.58688559917144E-05" ixy="-9.33412701053305E-06" ixz="-2.12947225160345E-07" iyy="1.98652848189388E-05" iyz="-9.66953808700748E-07" izz="0.000101234986556129"/>
    </inertial>
    <visual>
      <origin rpy="0 0 0" xyz="0 0 0"/>
      <geometry>
        <mesh filename="package://meshes/Gonio_Left/UV_Cart_Back.STL"/>
      </geometry>
      <material name="grey"/>
    </visual>
    <collision>
      <origin rpy="0 0 0" xyz="0 0 0"/>
      <geometry>
        <mesh filename="package://meshes/Gonio_Left/UV_Cart_Back.STL"/>
      </geometry>
    </collision>
  </link>
  <joint name="UV_LED_Back_Joint" type="prismatic">
    <origin rpy="0 0 0" xyz="0.0649999999999949 0.0539999999999998 0.0496999999948266"/>
    <parent link="UV_Slider_X_Back"/>
    <child link="UV_LED_Back"/>
    <axis xyz="0 1 0"/>
    <limit effort="100" lower="0" upper="0.05" velocity="0.05"/>
  </joint>
  <!--xacro:include filename="$(find pm_robot_description)/urdf/sensors.urdf" /-->
  <!-- Switch between Gazebo-Simulation and Real Robot -->
  <!-- <xacro:include filename="$(find pm_robot_description)/urdf/ros2_control_real.xacro" /> -->
  <ros2_control name="GazeboSystem" type="system">
    <hardware>
      <plugin>gazebo_ros2_control/GazeboSystem</plugin>
    </hardware>
    <joint name="X_Axis_Joint">
      <command_interface name="position"/>
      <!-- <command_interface name="velocity"/> -->
      <state_interface name="position"/>
      <state_interface name="velocity"/>
    </joint>
    <joint name="Y_Axis_Joint">
      <command_interface name="position">
                </command_interface>
      <state_interface name="position"/>
      <state_interface name="velocity"/>
    </joint>
    <joint name="Z_Axis_Joint">
      <command_interface name="position">
                </command_interface>
      <state_interface name="position"/>
      <state_interface name="velocity"/>
    </joint>
    <joint name="T_Axis_Joint">
      <command_interface name="position">
                </command_interface>
      <state_interface name="position"/>
      <state_interface name="velocity"/>
    </joint>
    <joint name="1K_Dispenser_Flap_Joint">
      <command_interface name="position">
                </command_interface>
      <state_interface name="position"/>
    </joint>
    <joint name="1K_Dispenser_Joint">
      <command_interface name="position">
                </command_interface>
      <state_interface name="position"/>
    </joint>
    <joint name="2K_Dispenser_Joint">
      <command_interface name="position">
                </command_interface>
      <state_interface name="position"/>
    </joint>
    <joint name="Gonio_Right_Stage_1_Joint">
      <command_interface name="position">
                </command_interface>
      <state_interface name="position"/>
    </joint>
    <joint name="Gonio_Right_Stage_2_Joint">
      <command_interface name="position">
                </command_interface>
      <state_interface name="position"/>
    </joint>
    <joint name="Camera_Calibration_Platelet_Joint">
      <command_interface name="position">
                </command_interface>
      <state_interface name="position"/>
    </joint>
    <joint name="Gonio_Left_Stage_1_Joint">
      <command_interface name="position">
                </command_interface>
      <state_interface name="position"/>
    </joint>
    <joint name="Gonio_Left_Stage_2_Joint">
      <command_interface name="position">
                </command_interface>
      <state_interface name="position"/>
    </joint>
    <joint name="UV_Slider_X_Front_Joint">
      <command_interface name="position">
                </command_interface>
      <state_interface name="position"/>
    </joint>
    <joint name="UV_LED_Front_Joint">
      <command_interface name="position">
                </command_interface>
      <state_interface name="position"/>
    </joint>
    <joint name="UV_Slider_X_Back_Joint">
      <command_interface name="position">
                </command_interface>
      <state_interface name="position"/>
    </joint>
    <joint name="UV_LED_Back_Joint">
      <command_interface name="position">
                </command_interface>
      <state_interface name="position"/>
    </joint>
    <joint name="Calibration_Qube_Joint">
      <command_interface name="position">
                </command_interface>
      <state_interface name="position"/>
    </joint>
    <joint name="pm_robot_Tool_Parallel_Joint">
      <command_interface name="position">
                    </command_interface>
      <state_interface name="position"/>
      <state_interface name="velocity"/>
    </joint>
    <joint name="pm_robot_Tool_Parallel_Joint_mimic">
      <param name="mimic">pm_robot_Tool_Parallel_Joint</param>
      <param name="mulltiplier">1</param>
      <command_interface name="position">
                    </command_interface>
      <state_interface name="position"/>
      <state_interface name="velocity"/>
    </joint>
  </ros2_control>
  <gazebo>
    <plugin filename="libgazebo_ros2_control.so" name="gazebo_ros2_control">
      <parameters>/home/match-mover/Documents/ros2_ws/install/pm_robot_description/share/pm_robot_description/config/pm_robot_control_fakeHW.yaml</parameters>
      <parameters>/home/match-mover/Documents/ros2_ws/install/pm_robot_description/share/pm_robot_description/config/pm_robot_control_gonio_right.yaml</parameters>
      <parameters>/home/match-mover/Documents/ros2_ws/install/pm_robot_description/share/pm_robot_description/config/pm_robot_control_gonio_left.yaml</parameters>
      <parameters>/home/match-mover/Documents/ros2_ws/install/pm_robot_description/share/pm_robot_description/config/pm_robot_control_gripper.yaml</parameters>
      <parameters>/home/match-mover/Documents/ros2_ws/install/pm_robot_description/share/pm_robot_description/config/pm_robot_control_gazebo_param.yaml</parameters>
      <!--robot_param>robot_description</robot_param-->
      <!--The location of the robot_description (URDF) on the parameter server, defaults to robot_description-->
      <!--robot_param_node>robot_state_publisher</robot_param_node-->
      <!-- Name of the node where the robot_param is located, defauls to robot_state_publisher-->
      <!--robotNamespace>${arm_id}</robotNamespace-->
    </plugin>
  </gazebo>
</robot>
